2024-12-01 15:04:10,529 - WARNING -  * Debugger is active!
2024-12-01 15:04:10,534 - INFO -  * Debugger PIN: 245-605-918
2024-12-01 15:05:00,888 - INFO - 127.0.0.1 - - [01/Dec/2024 15:05:00] "[35m[1mPOST /send_message HTTP/1.1[0m" 500 -
2024-12-01 15:07:57,094 - INFO - 127.0.0.1 - - [01/Dec/2024 15:07:57] "[35m[1mPOST /send_message HTTP/1.1[0m" 500 -
2024-12-01 15:08:04,580 - INFO - 127.0.0.1 - - [01/Dec/2024 15:08:04] "[33mPOST /voice_input HTTP/1.1[0m" 404 -
2024-12-01 15:08:18,966 - INFO - 127.0.0.1 - - [01/Dec/2024 15:08:18] "POST /talking_mode HTTP/1.1" 200 -
2024-12-01 15:08:18,979 - INFO - 127.0.0.1 - - [01/Dec/2024 15:08:18] "[33mGET /cdn-cgi/styles/main.css HTTP/1.1[0m" 404 -
2024-12-01 15:12:41,140 - INFO - 127.0.0.1 - - [01/Dec/2024 15:12:41] "GET / HTTP/1.1" 200 -
2024-12-01 15:12:42,057 - INFO - 127.0.0.1 - - [01/Dec/2024 15:12:42] "[36mGET /static/style.css HTTP/1.1[0m" 304 -
2024-12-01 15:12:50,545 - INFO - 127.0.0.1 - - [01/Dec/2024 15:12:50] "[35m[1mPOST /send_message HTTP/1.1[0m" 500 -
2024-12-01 15:16:13,895 - INFO - [31m[1mWARNING: This is a development server. Do not use it in a production deployment. Use a production WSGI server instead.[0m
 * Running on http://127.0.0.1:5000
2024-12-01 15:16:13,911 - INFO - [33mPress CTRL+C to quit[0m
2024-12-01 15:16:13,915 - INFO -  * Restarting with stat
2024-12-01 15:16:17,405 - WARNING -  * Debugger is active!
2024-12-01 15:16:17,418 - INFO -  * Debugger PIN: 245-605-918
2024-12-01 15:16:23,865 - INFO - 127.0.0.1 - - [01/Dec/2024 15:16:23] "GET / HTTP/1.1" 200 -
2024-12-01 15:16:25,369 - INFO - 127.0.0.1 - - [01/Dec/2024 15:16:25] "[36mGET /static/style.css HTTP/1.1[0m" 304 -
2024-12-01 15:16:38,021 - INFO - 127.0.0.1 - - [01/Dec/2024 15:16:38] "[35m[1mPOST /send_message HTTP/1.1[0m" 500 -
2024-12-01 15:16:38,375 - INFO - 127.0.0.1 - - [01/Dec/2024 15:16:38] "[35m[1mPOST /send_message HTTP/1.1[0m" 500 -
2024-12-01 15:18:58,917 - INFO - [31m[1mWARNING: This is a development server. Do not use it in a production deployment. Use a production WSGI server instead.[0m
 * Running on http://127.0.0.1:5000
2024-12-01 15:18:58,917 - INFO - [33mPress CTRL+C to quit[0m
2024-12-01 15:18:58,921 - INFO -  * Restarting with stat
2024-12-01 15:19:01,531 - WARNING -  * Debugger is active!
2024-12-01 15:19:01,540 - INFO -  * Debugger PIN: 245-605-918
2024-12-01 15:19:10,844 - INFO - 127.0.0.1 - - [01/Dec/2024 15:19:10] "[35m[1mPOST /send_message HTTP/1.1[0m" 500 -
2024-12-01 15:19:13,733 - INFO - 127.0.0.1 - - [01/Dec/2024 15:19:13] "[36mGET /static/style.css HTTP/1.1[0m" 304 -
2024-12-01 15:20:12,827 - INFO -  * Detected change in 'E:\\Desktop\\IoT_Project\\AI-WaifuSistant\\Controller\\waifu.py', reloading
2024-12-01 15:20:13,189 - INFO -  * Restarting with stat
2024-12-01 15:20:17,671 - WARNING -  * Debugger is active!
2024-12-01 15:20:17,680 - INFO -  * Debugger PIN: 245-605-918
2024-12-01 15:20:31,427 - INFO - 127.0.0.1 - - [01/Dec/2024 15:20:31] "[35m[1mPOST /send_message HTTP/1.1[0m" 500 -
2024-12-01 15:20:31,910 - INFO - 127.0.0.1 - - [01/Dec/2024 15:20:31] "[35m[1mPOST /send_message HTTP/1.1[0m" 500 -
2024-12-07 17:13:21,630 - INFO - [31m[1mWARNING: This is a development server. Do not use it in a production deployment. Use a production WSGI server instead.[0m
 * Running on http://127.0.0.1:5000
2024-12-07 17:13:21,648 - INFO - [33mPress CTRL+C to quit[0m
2024-12-07 17:13:21,650 - INFO -  * Restarting with stat
2024-12-07 17:13:22,740 - WARNING -  * Debugger is active!
2024-12-07 17:13:22,742 - INFO -  * Debugger PIN: 118-397-831
2024-12-07 17:14:29,145 - INFO - [31m[1mWARNING: This is a development server. Do not use it in a production deployment. Use a production WSGI server instead.[0m
 * Running on http://127.0.0.1:5000
2024-12-07 17:14:29,145 - INFO - [33mPress CTRL+C to quit[0m
2024-12-07 17:14:29,147 - INFO -  * Restarting with stat
2024-12-07 17:14:30,168 - WARNING -  * Debugger is active!
2024-12-07 17:14:30,171 - INFO -  * Debugger PIN: 118-397-831
2024-12-07 17:15:50,896 - INFO - 127.0.0.1 - - [07/Dec/2024 17:15:50] "GET / HTTP/1.1" 200 -
2024-12-07 17:15:51,035 - INFO - 127.0.0.1 - - [07/Dec/2024 17:15:51] "GET /static/style.css HTTP/1.1" 200 -
2024-12-07 17:15:51,301 - INFO - 127.0.0.1 - - [07/Dec/2024 17:15:51] "[33mGET /favicon.ico HTTP/1.1[0m" 404 -
2024-12-07 17:16:33,452 - INFO - 127.0.0.1 - - [07/Dec/2024 17:16:33] "POST /send_message HTTP/1.1" 200 -
2024-12-07 17:17:00,537 - INFO - 127.0.0.1 - - [07/Dec/2024 17:17:00] "POST /send_message HTTP/1.1" 200 -
2024-12-07 17:17:46,936 - INFO - 127.0.0.1 - - [07/Dec/2024 17:17:46] "POST /send_message HTTP/1.1" 200 -
2024-12-07 17:18:32,811 - INFO - 127.0.0.1 - - [07/Dec/2024 17:18:32] "[33mPOST /voice_input HTTP/1.1[0m" 404 -
2024-12-07 17:20:35,312 - INFO - 127.0.0.1 - - [07/Dec/2024 17:20:35] "POST /talking_mode HTTP/1.1" 200 -
2024-12-07 17:22:02,442 - INFO - 127.0.0.1 - - [07/Dec/2024 17:22:02] "POST /talking_mode HTTP/1.1" 200 -
2024-12-07 17:31:58,648 - INFO - 127.0.0.1 - - [07/Dec/2024 17:31:58] "POST /talking_mode HTTP/1.1" 200 -
2024-12-07 19:38:35,480 - INFO -  * Detected change in 'E:\\Desktop\\IoT_Project\\AI-WaifuSistant\\app.py', reloading
2024-12-07 19:38:46,343 - INFO - [31m[1mWARNING: This is a development server. Do not use it in a production deployment. Use a production WSGI server instead.[0m
 * Running on http://127.0.0.1:5000
2024-12-07 19:38:46,343 - INFO - [33mPress CTRL+C to quit[0m
2024-12-07 19:38:46,345 - INFO -  * Restarting with stat
2024-12-07 19:38:47,256 - WARNING -  * Debugger is active!
2024-12-07 19:38:47,258 - INFO -  * Debugger PIN: 118-397-831
2024-12-07 19:48:25,301 - INFO - [31m[1mWARNING: This is a development server. Do not use it in a production deployment. Use a production WSGI server instead.[0m
 * Running on http://127.0.0.1:5000
2024-12-07 19:48:25,302 - INFO - [33mPress CTRL+C to quit[0m
2024-12-07 19:48:25,303 - INFO -  * Restarting with stat
2024-12-07 19:48:26,219 - WARNING -  * Debugger is active!
2024-12-07 19:48:26,222 - INFO -  * Debugger PIN: 118-397-831
2024-12-07 19:48:30,917 - INFO - 127.0.0.1 - - [07/Dec/2024 19:48:30] "GET / HTTP/1.1" 200 -
2024-12-07 19:48:31,060 - INFO - 127.0.0.1 - - [07/Dec/2024 19:48:31] "[36mGET /static/style.css HTTP/1.1[0m" 304 -
2024-12-07 19:48:45,496 - INFO - 127.0.0.1 - - [07/Dec/2024 19:48:45] "[35m[1mPOST /send_message HTTP/1.1[0m" 500 -
2024-12-07 19:49:55,641 - INFO -  * Detected change in 'E:\\Desktop\\IoT_Project\\AI-WaifuSistant\\app.py', reloading
2024-12-07 19:49:55,738 - INFO -  * Restarting with stat
2024-12-07 19:49:56,877 - WARNING -  * Debugger is active!
2024-12-07 19:49:56,880 - INFO -  * Debugger PIN: 118-397-831
2024-12-07 19:51:57,379 - INFO -  * Detected change in 'E:\\Desktop\\IoT_Project\\AI-WaifuSistant\\app.py', reloading
2024-12-07 19:51:57,505 - INFO -  * Restarting with stat
2024-12-07 19:54:52,505 - ERROR - Form data requires "python-multipart" to be installed. 
You can install "python-multipart" with: 

pip install python-multipart

2024-12-08 10:38:24,439 - ERROR - Error in send_message: Incorrect API key provided: zu-8ca9a***********************3966. You can find your API key at https://platform.openai.com/account/api-keys.
2024-12-08 10:41:10,171 - ERROR - Error in send_message: a coroutine was expected, got 'Apakah ada yang salah? Maaf, saya tidak paham apa yang kamu bicarakan. Ingat, kamu bisa mengulangi jika kamu butuh membicarakan sesuatu!'
2024-12-08 10:44:24,275 - ERROR - Error in send_message: object str can't be used in 'await' expression
2024-12-08 14:30:26,401 - ERROR - Error in send_message: Incorrect API key provided: zu-8ca9a***********************3966. You can find your API key at https://platform.openai.com/account/api-keys.
2024-12-08 14:30:38,349 - ERROR - Error in send_message: Incorrect API key provided: zu-8ca9a***********************3966. You can find your API key at https://platform.openai.com/account/api-keys.
2024-12-08 14:41:13,793 - ERROR - Error in talking_mode: object str can't be used in 'await' expression
2024-12-08 16:15:12,139 - ERROR - Error in talking_mode: The provider sent an invalid response. {
    "error": {
        "message": "The provider sent an invalid response.",
        "type": "error",
        "discord": "https://discord.gg/zukijourney",
        "param": null,
        "code": null
    }
} 500 {'error': {'message': 'The provider sent an invalid response.', 'type': 'error', 'discord': 'https://discord.gg/zukijourney', 'param': None, 'code': None}} {'Date': 'Sun, 08 Dec 2024 09:15:11 GMT', 'Content-Type': 'application/json', 'Content-Length': '207', 'Connection': 'keep-alive', 'CF-Cache-Status': 'DYNAMIC', 'Report-To': '{"endpoints":[{"url":"https:\\/\\/a.nel.cloudflare.com\\/report\\/v4?s=W%2FHk%2FmFw%2B95cCtDa1Jn8D4CLhwrzerL0Ta1DE5iQON8hfGtV2Br4X9D3XUUScJ1XtlsaAcc08Tw4h8OW4jUbdvs679CgFvjB33GpPkci1Ovv42jeYugco2ntUcK%2FGh63k7V4yO8t"}],"group":"cf-nel","max_age":604800}', 'NEL': '{"success_fraction":0,"report_to":"cf-nel","max_age":604800}', 'Server': 'cloudflare', 'CF-RAY': '8eeba6005c3b01e5-SIN', 'alt-svc': 'h3=":443"; ma=86400', 'server-timing': 'cfL4;desc="?proto=TCP&rtt=30010&min_rtt=14664&rtt_var=25324&sent=2118&recv=3710&lost=0&retrans=0&sent_bytes=8296&recv_bytes=5140755&delivery_rate=256836&cwnd=237&unsent_bytes=0&cid=7a83b381e0afaa8f&ts=118310&x=0"'}
2024-12-08 17:50:15,819 - ERROR - Error loading message history: Expecting value: line 1 column 1 (char 0)
2024-12-08 19:32:28,814 - ERROR - Error loading message history: Expecting value: line 1 column 1 (char 0)
2024-12-08 20:26:16,736 - ERROR - Error loading message history: Expecting value: line 1 column 1 (char 0)
2024-12-08 20:26:47,693 - ERROR - Error loading message history: Expecting value: line 1 column 1 (char 0)
2024-12-08 20:26:51,568 - ERROR - Error loading message history: Expecting value: line 1 column 1 (char 0)
2024-12-15 11:29:34,143 - ERROR - Error loading message history: Expecting value: line 1 column 1 (char 0)
2024-12-15 11:32:45,812 - ERROR - Error loading message history: Expecting value: line 1 column 1 (char 0)
2024-12-15 11:33:24,841 - ERROR - Error loading message history: Expecting value: line 1 column 1 (char 0)
2024-12-15 11:38:12,764 - ERROR - Error in send_message: Waifu.__edge_tts_generate() got an unexpected keyword argument 'is_ssml'
2024-12-15 11:42:19,406 - ERROR - Error loading message history: Expecting value: line 1 column 1 (char 0)
2024-12-15 11:42:44,967 - ERROR - Error in send_message: Communicate.__init__() got an unexpected keyword argument 'is_ssml'
2024-12-15 11:43:40,455 - ERROR - Error loading message history: Expecting value: line 1 column 1 (char 0)
2024-12-15 11:44:29,041 - ERROR - Error loading message history: Expecting value: line 1 column 1 (char 0)
2024-12-15 19:06:11,266 - ERROR - Error loading message history: Expecting value: line 1 column 1 (char 0)
2024-12-15 19:10:05,278 - ERROR - Error loading message history: Expecting value: line 1 column 1 (char 0)
2024-12-15 19:10:18,629 - ERROR - Error loading message history: Expecting value: line 1 column 1 (char 0)
2024-12-15 19:17:19,817 - ERROR - Error loading message history: Expecting value: line 1 column 1 (char 0)
2024-12-15 19:17:21,413 - ERROR - Error loading message history: Expecting value: line 1 column 1 (char 0)
2024-12-15 19:18:30,432 - ERROR - Error getting chatbot response: Incorrect API key provided: zu-8ca9a***********************3966. You can find your API key at https://platform.openai.com/account/api-keys.
2024-12-15 19:20:01,378 - ERROR - Error loading message history: Expecting value: line 1 column 1 (char 0)
2024-12-15 19:20:05,538 - ERROR - Error loading message history: Expecting value: line 1 column 1 (char 0)
2024-12-15 20:19:35,683 - ERROR - Error loading message history: Expecting value: line 1 column 1 (char 0)
2024-12-15 20:54:05,211 - ERROR - Error loading message history: Expecting value: line 1 column 1 (char 0)
2024-12-15 21:01:53,314 - ERROR - Error loading message history: Expecting value: line 1 column 1 (char 0)
2024-12-15 21:02:07,736 - ERROR - Error loading message history: Expecting value: line 1 column 1 (char 0)
2024-12-15 21:02:17,149 - ERROR - Error loading message history: Expecting value: line 1 column 1 (char 0)
2024-12-15 21:02:21,610 - ERROR - HTTP error while pinging https://api.zukijourney.com/v1: 404 - {"detail":"Not Found"}
2024-12-15 21:02:24,265 - ERROR - HTTP error while pinging https://api.zukijourney.com/v1: 404 - {"detail":"Not Found"}
2024-12-15 21:03:04,550 - ERROR - Error loading message history: Expecting value: line 1 column 1 (char 0)
2024-12-15 21:03:04,553 - ERROR - Error loading message history: Expecting value: line 1 column 1 (char 0)
2024-12-15 21:03:26,523 - ERROR - HTTP error while pinging https://api.zukijourney.com/v1: 404 - {"detail":"Not Found"}
2024-12-15 21:05:31,718 - ERROR - HTTP error while pinging https://api.zukijourney.com/v1: 404 - {"detail":"Not Found"}
2024-12-15 21:07:46,197 - ERROR - HTTP error while pinging https://api.zukijourney.com/v1: 404 - {"detail":"Not Found"}
2024-12-15 21:08:00,432 - ERROR - HTTP error while pinging https://api.zukijourney.com/v1: 404 - {"detail":"Not Found"}
2024-12-15 21:08:01,129 - ERROR - HTTP error while pinging https://api.zukijourney.com/v1: 404 - {"detail":"Not Found"}
2024-12-15 21:09:05,994 - ERROR - Error getting chatbot response: Traceback (most recent call last):
  File "/opt/venv/lib/python3.10/site-packages/httpx/_transports/default.py", line 101, in map_httpcore_exceptions
    yield
  File "/opt/venv/lib/python3.10/site-packages/httpx/_transports/default.py", line 394, in handle_async_request
    resp = await self._pool.handle_async_request(req)
  File "/opt/venv/lib/python3.10/site-packages/httpcore/_async/connection_pool.py", line 256, in handle_async_request
    raise exc from None
  File "/opt/venv/lib/python3.10/site-packages/httpcore/_async/connection_pool.py", line 236, in handle_async_request
    response = await connection.handle_async_request(
  File "/opt/venv/lib/python3.10/site-packages/httpcore/_async/connection.py", line 101, in handle_async_request
    raise exc
  File "/opt/venv/lib/python3.10/site-packages/httpcore/_async/connection.py", line 78, in handle_async_request
    stream = await self._connect(request)
  File "/opt/venv/lib/python3.10/site-packages/httpcore/_async/connection.py", line 124, in _connect
    stream = await self._network_backend.connect_tcp(**kwargs)
  File "/opt/venv/lib/python3.10/site-packages/httpcore/_backends/auto.py", line 31, in connect_tcp
    return await self._backend.connect_tcp(
  File "/opt/venv/lib/python3.10/site-packages/httpcore/_backends/anyio.py", line 113, in connect_tcp
    with map_exceptions(exc_map):
  File "/usr/local/lib/python3.10/contextlib.py", line 153, in __exit__
    self.gen.throw(typ, value, traceback)
  File "/opt/venv/lib/python3.10/site-packages/httpcore/_exceptions.py", line 14, in map_exceptions
    raise to_exc(exc) from exc
httpcore.ConnectError: All connection attempts failed

The above exception was the direct cause of the following exception:

Traceback (most recent call last):
  File "/app/src/providers/chat/multiple/litellm.py", line 137, in chat_completions
    response = await instance.client.send(
  File "/opt/venv/lib/python3.10/site-packages/httpx/_client.py", line 1629, in send
    response = await self._send_handling_auth(
  File "/opt/venv/lib/python3.10/site-packages/httpx/_client.py", line 1657, in _send_handling_auth
    response = await self._send_handling_redirects(
  File "/opt/venv/lib/python3.10/site-packages/httpx/_client.py", line 1694, in _send_handling_redirects
    response = await self._send_single_request(request)
  File "/opt/venv/lib/python3.10/site-packages/httpx/_client.py", line 1730, in _send_single_request
    response = await transport.handle_async_request(request)
  File "/opt/venv/lib/python3.10/site-packages/httpx/_transports/default.py", line 393, in handle_async_request
    with map_httpcore_exceptions():
  File "/usr/local/lib/python3.10/contextlib.py", line 153, in __exit__
    self.gen.throw(typ, value, traceback)
  File "/opt/venv/lib/python3.10/site-packages/httpx/_transports/default.py", line 118, in map_httpcore_exceptions
    raise mapped_exc(message) from exc
httpx.ConnectError: All connection attempts failed
 {
    "error": {
        "message": "Traceback (most recent call last):\n  File \"/opt/venv/lib/python3.10/site-packages/httpx/_transports/default.py\", line 101, in map_httpcore_exceptions\n    yield\n  File \"/opt/venv/lib/python3.10/site-packages/httpx/_transports/default.py\", line 394, in handle_async_request\n    resp = await self._pool.handle_async_request(req)\n  File \"/opt/venv/lib/python3.10/site-packages/httpcore/_async/connection_pool.py\", line 256, in handle_async_request\n    raise exc from None\n  File \"/opt/venv/lib/python3.10/site-packages/httpcore/_async/connection_pool.py\", line 236, in handle_async_request\n    response = await connection.handle_async_request(\n  File \"/opt/venv/lib/python3.10/site-packages/httpcore/_async/connection.py\", line 101, in handle_async_request\n    raise exc\n  File \"/opt/venv/lib/python3.10/site-packages/httpcore/_async/connection.py\", line 78, in handle_async_request\n    stream = await self._connect(request)\n  File \"/opt/venv/lib/python3.10/site-packages/httpcore/_async/connection.py\", line 124, in _connect\n    stream = await self._network_backend.connect_tcp(**kwargs)\n  File \"/opt/venv/lib/python3.10/site-packages/httpcore/_backends/auto.py\", line 31, in connect_tcp\n    return await self._backend.connect_tcp(\n  File \"/opt/venv/lib/python3.10/site-packages/httpcore/_backends/anyio.py\", line 113, in connect_tcp\n    with map_exceptions(exc_map):\n  File \"/usr/local/lib/python3.10/contextlib.py\", line 153, in __exit__\n    self.gen.throw(typ, value, traceback)\n  File \"/opt/venv/lib/python3.10/site-packages/httpcore/_exceptions.py\", line 14, in map_exceptions\n    raise to_exc(exc) from exc\nhttpcore.ConnectError: All connection attempts failed\n\nThe above exception was the direct cause of the following exception:\n\nTraceback (most recent call last):\n  File \"/app/src/providers/chat/multiple/litellm.py\", line 137, in chat_completions\n    response = await instance.client.send(\n  File \"/opt/venv/lib/python3.10/site-packages/httpx/_client.py\", line 1629, in send\n    response = await self._send_handling_auth(\n  File \"/opt/venv/lib/python3.10/site-packages/httpx/_client.py\", line 1657, in _send_handling_auth\n    response = await self._send_handling_redirects(\n  File \"/opt/venv/lib/python3.10/site-packages/httpx/_client.py\", line 1694, in _send_handling_redirects\n    response = await self._send_single_request(request)\n  File \"/opt/venv/lib/python3.10/site-packages/httpx/_client.py\", line 1730, in _send_single_request\n    response = await transport.handle_async_request(request)\n  File \"/opt/venv/lib/python3.10/site-packages/httpx/_transports/default.py\", line 393, in handle_async_request\n    with map_httpcore_exceptions():\n  File \"/usr/local/lib/python3.10/contextlib.py\", line 153, in __exit__\n    self.gen.throw(typ, value, traceback)\n  File \"/opt/venv/lib/python3.10/site-packages/httpx/_transports/default.py\", line 118, in map_httpcore_exceptions\n    raise mapped_exc(message) from exc\nhttpx.ConnectError: All connection attempts failed\n", 
        "provider_id": "llm", 
        "type": "invalid_response_error", 
        "code": 500
    }
} 500 {'error': {'message': 'Traceback (most recent call last):\n  File "/opt/venv/lib/python3.10/site-packages/httpx/_transports/default.py", line 101, in map_httpcore_exceptions\n    yield\n  File "/opt/venv/lib/python3.10/site-packages/httpx/_transports/default.py", line 394, in handle_async_request\n    resp = await self._pool.handle_async_request(req)\n  File "/opt/venv/lib/python3.10/site-packages/httpcore/_async/connection_pool.py", line 256, in handle_async_request\n    raise exc from None\n  File "/opt/venv/lib/python3.10/site-packages/httpcore/_async/connection_pool.py", line 236, in handle_async_request\n    response = await connection.handle_async_request(\n  File "/opt/venv/lib/python3.10/site-packages/httpcore/_async/connection.py", line 101, in handle_async_request\n    raise exc\n  File "/opt/venv/lib/python3.10/site-packages/httpcore/_async/connection.py", line 78, in handle_async_request\n    stream = await self._connect(request)\n  File "/opt/venv/lib/python3.10/site-packages/httpcore/_async/connection.py", line 124, in _connect\n    stream = await self._network_backend.connect_tcp(**kwargs)\n  File "/opt/venv/lib/python3.10/site-packages/httpcore/_backends/auto.py", line 31, in connect_tcp\n    return await self._backend.connect_tcp(\n  File "/opt/venv/lib/python3.10/site-packages/httpcore/_backends/anyio.py", line 113, in connect_tcp\n    with map_exceptions(exc_map):\n  File "/usr/local/lib/python3.10/contextlib.py", line 153, in __exit__\n    self.gen.throw(typ, value, traceback)\n  File "/opt/venv/lib/python3.10/site-packages/httpcore/_exceptions.py", line 14, in map_exceptions\n    raise to_exc(exc) from exc\nhttpcore.ConnectError: All connection attempts failed\n\nThe above exception was the direct cause of the following exception:\n\nTraceback (most recent call last):\n  File "/app/src/providers/chat/multiple/litellm.py", line 137, in chat_completions\n    response = await instance.client.send(\n  File "/opt/venv/lib/python3.10/site-packages/httpx/_client.py", line 1629, in send\n    response = await self._send_handling_auth(\n  File "/opt/venv/lib/python3.10/site-packages/httpx/_client.py", line 1657, in _send_handling_auth\n    response = await self._send_handling_redirects(\n  File "/opt/venv/lib/python3.10/site-packages/httpx/_client.py", line 1694, in _send_handling_redirects\n    response = await self._send_single_request(request)\n  File "/opt/venv/lib/python3.10/site-packages/httpx/_client.py", line 1730, in _send_single_request\n    response = await transport.handle_async_request(request)\n  File "/opt/venv/lib/python3.10/site-packages/httpx/_transports/default.py", line 393, in handle_async_request\n    with map_httpcore_exceptions():\n  File "/usr/local/lib/python3.10/contextlib.py", line 153, in __exit__\n    self.gen.throw(typ, value, traceback)\n  File "/opt/venv/lib/python3.10/site-packages/httpx/_transports/default.py", line 118, in map_httpcore_exceptions\n    raise mapped_exc(message) from exc\nhttpx.ConnectError: All connection attempts failed\n', 'provider_id': 'llm', 'type': 'invalid_response_error', 'code': 500}} {'Date': 'Sun, 15 Dec 2024 14:09:05 GMT', 'Content-Type': 'application/json', 'Content-Length': '3196', 'Connection': 'keep-alive', 'CF-Cache-Status': 'DYNAMIC', 'Report-To': '{"endpoints":[{"url":"https:\\/\\/a.nel.cloudflare.com\\/report\\/v4?s=6j3%2BdETTszfYsUN5h287m4WsaqTx7BkxTJxBB3TfYY1%2BhSAKBxQw2oI3Hfs0lC%2BLPVz2Letslz9vjX3ZUIaDGMwRWLCRNen%2BVm59rPEuG43YDBtiYAAP6tsOcdguyaGHkKCXgbq2"}],"group":"cf-nel","max_age":604800}', 'NEL': '{"success_fraction":0,"report_to":"cf-nel","max_age":604800}', 'Server': 'cloudflare', 'CF-RAY': '8f27025ac9eda8fa-SIN', 'alt-svc': 'h3=":443"; ma=86400', 'server-timing': 'cfL4;desc="?proto=TCP&rtt=19771&min_rtt=14340&rtt_var=11944&sent=18&recv=18&lost=0&retrans=0&sent_bytes=6129&recv_bytes=7416&delivery_rate=253652&cwnd=257&unsent_bytes=0&cid=c86a24c7ba89d5fa&ts=56123&x=0"'}
2024-12-15 21:12:25,343 - ERROR - Error loading message history: Expecting value: line 1 column 1 (char 0)
2024-12-15 21:12:25,343 - ERROR - Error loading message history: Expecting value: line 1 column 1 (char 0)
2024-12-15 21:19:56,433 - ERROR - Error loading message history: Expecting value: line 1 column 1 (char 0)
2024-12-15 21:30:41,491 - ERROR - Error getting chatbot response: You have 764.0 credits left. This request requires 1224 credits.
2024-12-15 21:31:09,031 - ERROR - Error getting chatbot response: You have 764.0 credits left. This request requires 1224 credits.
2024-12-15 21:31:19,798 - ERROR - Error getting chatbot response: You have 764.0 credits left. This request requires 1227 credits.
2024-12-20 17:03:36,699 - ERROR - Error loading message history: Expecting value: line 1 column 1 (char 0)
2024-12-20 17:04:02,317 - ERROR - Error getting chatbot response: Your IP is different than the locked one. Reset your IP lock at: http://discord.gg/zukijourney
2024-12-20 17:11:25,664 - ERROR - Error loading message history: Expecting value: line 1 column 1 (char 0)
2024-12-20 17:12:52,796 - ERROR - Error getting chatbot response: Your IP is different than the locked one. Reset your IP lock at: http://discord.gg/zukijourney
2024-12-20 17:14:52,995 - ERROR - Error loading message history: Expecting value: line 1 column 1 (char 0)
2024-12-20 17:15:03,826 - ERROR - Error getting chatbot response: Your IP is different than the locked one. Reset your IP lock at: http://discord.gg/zukijourney
2024-12-20 17:15:03,826 - ERROR - Error in send_message: Communicate.__init__() got an unexpected keyword argument 'ssml'
2024-12-20 17:15:14,650 - ERROR - Error loading message history: Expecting value: line 1 column 1 (char 0)
2024-12-20 17:15:20,487 - ERROR - Error getting chatbot response: Your IP is different than the locked one. Reset your IP lock at: http://discord.gg/zukijourney
2024-12-20 17:15:20,487 - ERROR - Error in send_message: Communicate.__init__() got an unexpected keyword argument 'ssml'
2024-12-20 17:15:27,616 - ERROR - Error loading message history: Expecting value: line 1 column 1 (char 0)
2024-12-20 17:15:39,708 - ERROR - Error getting chatbot response: Your IP is different than the locked one. Reset your IP lock at: http://discord.gg/zukijourney
2024-12-20 17:15:39,708 - ERROR - Error in send_message: Communicate.__init__() got an unexpected keyword argument 'ssml'
2024-12-20 17:16:25,789 - ERROR - Error loading message history: Expecting value: line 1 column 1 (char 0)
2024-12-20 17:16:35,356 - ERROR - Error getting chatbot response: Your IP is different than the locked one. Reset your IP lock at: http://discord.gg/zukijourney
2024-12-20 17:18:10,476 - ERROR - Error loading message history: Expecting value: line 1 column 1 (char 0)
2024-12-20 17:18:12,398 - ERROR - Error loading message history: Expecting value: line 1 column 1 (char 0)
2024-12-20 17:18:25,541 - ERROR - Error getting chatbot response: Your IP is different than the locked one. Reset your IP lock at: http://discord.gg/zukijourney
2024-12-20 17:18:25,541 - ERROR - Error in send_message: Communicate.__init__() got an unexpected keyword argument 'is_ssml'
2024-12-20 17:19:38,599 - ERROR - Error loading message history: Expecting value: line 1 column 1 (char 0)
2024-12-20 17:19:50,774 - ERROR - Error getting chatbot response: Your IP is different than the locked one. Reset your IP lock at: http://discord.gg/zukijourney
2024-12-20 17:19:50,774 - ERROR - Error in send_message: Communicate.__init__() got an unexpected keyword argument 'is_ssml'
2024-12-20 17:20:20,559 - ERROR - Error loading message history: Expecting value: line 1 column 1 (char 0)
2024-12-20 17:20:26,437 - ERROR - Error getting chatbot response: Your IP is different than the locked one. Reset your IP lock at: http://discord.gg/zukijourney
2024-12-20 17:23:34,450 - ERROR - Error loading message history: Expecting value: line 1 column 1 (char 0)
2024-12-20 17:23:37,181 - ERROR - Error loading message history: Expecting value: line 1 column 1 (char 0)
2024-12-20 17:25:02,644 - ERROR - Error loading message history: Expecting value: line 1 column 1 (char 0)
2024-12-20 17:25:21,742 - ERROR - Error getting chatbot response: Your IP is different than the locked one. Reset your IP lock at: http://discord.gg/zukijourney
2024-12-20 17:27:15,326 - ERROR - Error loading message history: Expecting value: line 1 column 1 (char 0)
2024-12-20 17:34:16,876 - ERROR - Error loading message history: Expecting value: line 1 column 1 (char 0)
2024-12-20 17:34:31,379 - ERROR - Error getting chatbot response: Your IP is different than the locked one. Reset your IP lock at: http://discord.gg/zukijourney
2024-12-20 17:34:42,413 - ERROR - Error getting chatbot response: Your IP is different than the locked one. Reset your IP lock at: http://discord.gg/zukijourney
2024-12-20 17:35:08,948 - ERROR - Error loading message history: Expecting value: line 1 column 1 (char 0)
2024-12-20 17:35:29,043 - ERROR - Error getting chatbot response: Your IP is different than the locked one. Reset your IP lock at: http://discord.gg/zukijourney
2024-12-20 17:35:42,001 - ERROR - Error getting chatbot response: Your IP is different than the locked one. Reset your IP lock at: http://discord.gg/zukijourney
2024-12-20 17:36:07,562 - ERROR - Error loading message history: Expecting value: line 1 column 1 (char 0)
2024-12-21 16:55:18,768 - ERROR - Error loading message history: Expecting value: line 1 column 1 (char 0)
2024-12-21 16:56:49,529 - ERROR - Error getting chatbot response: Your IP is different than the locked one. Reset your IP lock at: http://discord.gg/zukijourney
2024-12-21 16:57:24,524 - ERROR - Error getting chatbot response: Your IP is different than the locked one. Reset your IP lock at: http://discord.gg/zukijourney
2024-12-21 16:58:20,694 - ERROR - Error loading message history: Expecting value: line 1 column 1 (char 0)
2024-12-21 16:58:29,041 - ERROR - Error getting chatbot response: Your IP is different than the locked one. Reset your IP lock at: http://discord.gg/zukijourney
2024-12-21 17:03:53,848 - ERROR - Error loading message history: Expecting value: line 1 column 1 (char 0)
2024-12-21 17:04:52,459 - ERROR - Error getting chatbot response: Your IP is different than the locked one. Reset your IP lock at: http://discord.gg/zukijourney
2024-12-21 17:07:31,164 - ERROR - Error getting chatbot response: Your IP is different than the locked one. Reset your IP lock at: http://discord.gg/zukijourney
2024-12-21 17:11:22,587 - ERROR - Error loading message history: Expecting value: line 1 column 1 (char 0)
2024-12-21 17:11:31,340 - ERROR - Error loading message history: Expecting value: line 1 column 1 (char 0)
2024-12-21 17:11:35,581 - ERROR - Error getting chatbot response: Your IP is different than the locked one. Reset your IP lock at: http://discord.gg/zukijourney
2024-12-21 17:12:15,939 - ERROR - Error loading message history: Expecting value: line 1 column 1 (char 0)
2024-12-21 17:12:17,656 - ERROR - Error loading message history: Expecting value: line 1 column 1 (char 0)
2024-12-21 17:12:28,549 - ERROR - Error getting chatbot response: Your IP is different than the locked one. Reset your IP lock at: http://discord.gg/zukijourney
2024-12-21 17:13:04,206 - ERROR - Error loading message history: Expecting value: line 1 column 1 (char 0)
2024-12-21 17:13:09,905 - ERROR - Error loading message history: Expecting value: line 1 column 1 (char 0)
2024-12-21 17:13:16,202 - ERROR - Error getting chatbot response: Your IP is different than the locked one. Reset your IP lock at: http://discord.gg/zukijourney
2024-12-21 17:13:58,232 - ERROR - Error loading message history: Expecting value: line 1 column 1 (char 0)
2024-12-21 17:14:04,784 - ERROR - Error loading message history: Expecting value: line 1 column 1 (char 0)
2024-12-21 17:14:09,758 - ERROR - Error getting chatbot response: Your IP is different than the locked one. Reset your IP lock at: http://discord.gg/zukijourney
2024-12-21 17:19:24,781 - ERROR - Error loading message history: Expecting value: line 1 column 1 (char 0)
2024-12-21 17:20:09,777 - ERROR - Error loading message history: Expecting value: line 1 column 1 (char 0)
2024-12-21 17:20:25,135 - ERROR - Error loading message history: Expecting value: line 1 column 1 (char 0)
2024-12-21 17:20:29,485 - ERROR - Error getting chatbot response: Your IP is different than the locked one. Reset your IP lock at: http://discord.gg/zukijourney
2024-12-21 17:22:03,294 - ERROR - Error getting chatbot response: Your IP is different than the locked one. Reset your IP lock at: http://discord.gg/zukijourney
2024-12-21 17:23:07,390 - ERROR - Error loading message history: Expecting value: line 1 column 1 (char 0)
2024-12-21 17:26:10,334 - ERROR - Error loading message history: Expecting value: line 1 column 1 (char 0)
2024-12-21 17:36:44,895 - ERROR - Error loading message history: Expecting value: line 1 column 1 (char 0)
2024-12-21 17:41:26,946 - ERROR - Error loading message history: Expecting value: line 1 column 1 (char 0)
2024-12-21 17:43:25,651 - ERROR - Error loading message history: Expecting value: line 1 column 1 (char 0)
2024-12-21 17:52:54,382 - ERROR - Error loading message history: Expecting value: line 1 column 1 (char 0)
2024-12-21 18:06:33,725 - ERROR - Error loading message history: Expecting value: line 1 column 1 (char 0)
2024-12-21 18:12:00,369 - ERROR - Error in talking_mode: Traceback (most recent call last):
  File "/app/src/api/routes/v1/audio/transcriptions.py", line 54, in audio_transcriptions
    token_count = AudioHandler._get_token_count(
                  ^^^^^^^^^^^^^^^^^^^^^^^^^^^^^^
TypeError: AudioHandler._get_token_count() got an unexpected keyword argument 'provider_instance'
 {
    "error": {
        "message": "Traceback (most recent call last):\n  File \"/app/src/api/routes/v1/audio/transcriptions.py\", line 54, in audio_transcriptions\n    token_count = AudioHandler._get_token_count(\n                  ^^^^^^^^^^^^^^^^^^^^^^^^^^^^^^\nTypeError: AudioHandler._get_token_count() got an unexpected keyword argument 'provider_instance'\n", 
        "type": "invalid_request_error", 
        "code": 500
    }
} 500 {'error': {'message': 'Traceback (most recent call last):\n  File "/app/src/api/routes/v1/audio/transcriptions.py", line 54, in audio_transcriptions\n    token_count = AudioHandler._get_token_count(\n                  ^^^^^^^^^^^^^^^^^^^^^^^^^^^^^^\nTypeError: AudioHandler._get_token_count() got an unexpected keyword argument \'provider_instance\'\n', 'type': 'invalid_request_error', 'code': 500}} {'Date': 'Sat, 21 Dec 2024 11:12:00 GMT', 'Content-Type': 'application/json', 'Content-Length': '438', 'Connection': 'keep-alive', 'cf-cache-status': 'DYNAMIC', 'Report-To': '{"endpoints":[{"url":"https:\\/\\/a.nel.cloudflare.com\\/report\\/v4?s=Jpnwa7JnIPOcr6Y4eNSqF%2B2QsgzVY88XxQ9tuw7w3UVvEWAqERR4XwoXdRAumGKVikZpYFJxQ%2BC1Gj34MXwgugaBgl9hEhhVevTJsEZYPtd8UM3f%2BFxbzZQK09T8hy%2F8j6o%2FAMX9"}],"group":"cf-nel","max_age":604800}', 'NEL': '{"success_fraction":0,"report_to":"cf-nel","max_age":604800}', 'Server': 'cloudflare', 'CF-RAY': '8f576f39c9ca40d9-SIN', 'alt-svc': 'h3=":443"; ma=86400', 'server-timing': 'cfL4;desc="?proto=TCP&rtt=15858&min_rtt=15798&rtt_var=6044&sent=67&recv=116&lost=0&retrans=0&sent_bytes=2852&recv_bytes=153300&delivery_rate=260228&cwnd=250&unsent_bytes=0&cid=fd1fda91f4c78cca&ts=1344&x=0"'}
2024-12-21 18:13:10,217 - ERROR - Error in talking_mode: Traceback (most recent call last):
  File "/app/src/api/routes/v1/audio/transcriptions.py", line 54, in audio_transcriptions
    token_count = AudioHandler._get_token_count(
                  ^^^^^^^^^^^^^^^^^^^^^^^^^^^^^^
TypeError: AudioHandler._get_token_count() got an unexpected keyword argument 'provider_instance'
 {
    "error": {
        "message": "Traceback (most recent call last):\n  File \"/app/src/api/routes/v1/audio/transcriptions.py\", line 54, in audio_transcriptions\n    token_count = AudioHandler._get_token_count(\n                  ^^^^^^^^^^^^^^^^^^^^^^^^^^^^^^\nTypeError: AudioHandler._get_token_count() got an unexpected keyword argument 'provider_instance'\n", 
        "type": "invalid_request_error", 
        "code": 500
    }
} 500 {'error': {'message': 'Traceback (most recent call last):\n  File "/app/src/api/routes/v1/audio/transcriptions.py", line 54, in audio_transcriptions\n    token_count = AudioHandler._get_token_count(\n                  ^^^^^^^^^^^^^^^^^^^^^^^^^^^^^^\nTypeError: AudioHandler._get_token_count() got an unexpected keyword argument \'provider_instance\'\n', 'type': 'invalid_request_error', 'code': 500}} {'Date': 'Sat, 21 Dec 2024 11:13:10 GMT', 'Content-Type': 'application/json', 'Content-Length': '438', 'Connection': 'keep-alive', 'cf-cache-status': 'DYNAMIC', 'Report-To': '{"endpoints":[{"url":"https:\\/\\/a.nel.cloudflare.com\\/report\\/v4?s=WHyLe4PtSGsCUIFnM2V3UHWD04GB0U19PcG%2B794cczoiLff3Y6NSJRNkR86og7Bi3CC%2FNlrG%2B7vlmK97IZyF8M%2FnRqYmWpTcGKbMQMuM05XAXvirVl0GqA60aSglymYVTzF58gLn"}],"group":"cf-nel","max_age":604800}', 'NEL': '{"success_fraction":0,"report_to":"cf-nel","max_age":604800}', 'Server': 'cloudflare', 'CF-RAY': '8f5770e60e4c40d9-SIN', 'alt-svc': 'h3=":443"; ma=86400', 'server-timing': 'cfL4;desc="?proto=TCP&rtt=15768&min_rtt=15141&rtt_var=4712&sent=317&recv=552&lost=0&retrans=0&sent_bytes=4621&recv_bytes=757157&delivery_rate=260228&cwnd=252&unsent_bytes=0&cid=fd1fda91f4c78cca&ts=71192&x=0"'}
2024-12-21 18:23:09,675 - ERROR - Error loading message history: Expecting value: line 1 column 1 (char 0)
2024-12-22 11:54:12,712 - ERROR - Error loading message history: Expecting value: line 1 column 1 (char 0)
2024-12-22 11:54:46,564 - ERROR - Error in talking_mode: Traceback (most recent call last):
  File "/app/src/api/routes/v1/audio/transcriptions.py", line 54, in audio_transcriptions
    token_count = AudioHandler._get_token_count(
                  ^^^^^^^^^^^^^^^^^^^^^^^^^^^^^^
TypeError: AudioHandler._get_token_count() got an unexpected keyword argument 'provider_instance'
 {
    "error": {
        "message": "Traceback (most recent call last):\n  File \"/app/src/api/routes/v1/audio/transcriptions.py\", line 54, in audio_transcriptions\n    token_count = AudioHandler._get_token_count(\n                  ^^^^^^^^^^^^^^^^^^^^^^^^^^^^^^\nTypeError: AudioHandler._get_token_count() got an unexpected keyword argument 'provider_instance'\n", 
        "type": "invalid_request_error", 
        "code": 500
    }
} 500 {'error': {'message': 'Traceback (most recent call last):\n  File "/app/src/api/routes/v1/audio/transcriptions.py", line 54, in audio_transcriptions\n    token_count = AudioHandler._get_token_count(\n                  ^^^^^^^^^^^^^^^^^^^^^^^^^^^^^^\nTypeError: AudioHandler._get_token_count() got an unexpected keyword argument \'provider_instance\'\n', 'type': 'invalid_request_error', 'code': 500}} {'Date': 'Sun, 22 Dec 2024 04:54:46 GMT', 'Content-Type': 'application/json', 'Content-Length': '438', 'Connection': 'keep-alive', 'cf-cache-status': 'DYNAMIC', 'Report-To': '{"endpoints":[{"url":"https:\\/\\/a.nel.cloudflare.com\\/report\\/v4?s=9RsdxrclMrm7TlbNhew%2F7ntd8x9oaTc9u%2FozVqiuF2wYM3WSKSRLdWTrDXHQ3TI5nU5A%2Fej3fWcnjV%2FeYzzGK6HU%2BRYDUHa22EG3%2Bk9kevK6wGk5GlNhhClEbxlS2IHl1lTYYTQN"}],"group":"cf-nel","max_age":604800}', 'NEL': '{"success_fraction":0,"report_to":"cf-nel","max_age":604800}', 'Server': 'cloudflare', 'CF-RAY': '8f5d83fbaf12fce4-SIN', 'alt-svc': 'h3=":443"; ma=86400', 'server-timing': 'cfL4;desc="?proto=TCP&rtt=15500&min_rtt=15379&rtt_var=6010&sent=277&recv=378&lost=0&retrans=0&sent_bytes=2852&recv_bytes=514232&delivery_rate=259066&cwnd=252&unsent_bytes=0&cid=222cf2c125f536c4&ts=2609&x=0"'}
2024-12-22 11:59:56,906 - ERROR - Error loading message history: Expecting value: line 1 column 1 (char 0)
2024-12-22 12:00:13,870 - ERROR - Error in talking_mode: Traceback (most recent call last):
  File "/app/src/api/routes/v1/audio/transcriptions.py", line 54, in audio_transcriptions
    token_count = AudioHandler._get_token_count(
                  ^^^^^^^^^^^^^^^^^^^^^^^^^^^^^^
TypeError: AudioHandler._get_token_count() got an unexpected keyword argument 'provider_instance'
 {
    "error": {
        "message": "Traceback (most recent call last):\n  File \"/app/src/api/routes/v1/audio/transcriptions.py\", line 54, in audio_transcriptions\n    token_count = AudioHandler._get_token_count(\n                  ^^^^^^^^^^^^^^^^^^^^^^^^^^^^^^\nTypeError: AudioHandler._get_token_count() got an unexpected keyword argument 'provider_instance'\n", 
        "type": "invalid_request_error", 
        "code": 500
    }
} 500 {'error': {'message': 'Traceback (most recent call last):\n  File "/app/src/api/routes/v1/audio/transcriptions.py", line 54, in audio_transcriptions\n    token_count = AudioHandler._get_token_count(\n                  ^^^^^^^^^^^^^^^^^^^^^^^^^^^^^^\nTypeError: AudioHandler._get_token_count() got an unexpected keyword argument \'provider_instance\'\n', 'type': 'invalid_request_error', 'code': 500}} {'Date': 'Sun, 22 Dec 2024 05:00:13 GMT', 'Content-Type': 'application/json', 'Content-Length': '438', 'Connection': 'keep-alive', 'cf-cache-status': 'DYNAMIC', 'Report-To': '{"endpoints":[{"url":"https:\\/\\/a.nel.cloudflare.com\\/report\\/v4?s=bwgn%2FbtEzuKRpx9REe%2FvhUU2PnDxk3dOLfvvj6FxX73UwObtN9sW2e3RVbLZyoKjiKXkJsjPFk5%2BkL1RvEK72R1aev0UK2vybLI8Ng8szg30jIl1f52D%2BsLXS2xWcAboSZpJNXRc"}],"group":"cf-nel","max_age":604800}', 'NEL': '{"success_fraction":0,"report_to":"cf-nel","max_age":604800}', 'Server': 'cloudflare', 'CF-RAY': '8f5d8bff2bab44bb-SIN', 'alt-svc': 'h3=":443"; ma=86400', 'server-timing': 'cfL4;desc="?proto=TCP&rtt=16655&min_rtt=16571&rtt_var=6382&sent=60&recv=110&lost=0&retrans=0&sent_bytes=2853&recv_bytes=145086&delivery_rate=245664&cwnd=252&unsent_bytes=0&cid=f71927685f7a1446&ts=1675&x=0"'}
2024-12-22 12:08:47,866 - ERROR - Error loading message history: Expecting value: line 1 column 1 (char 0)
2024-12-22 12:09:00,046 - ERROR - Error in talking_mode: Traceback (most recent call last):
  File "/app/src/api/routes/v1/audio/transcriptions.py", line 54, in audio_transcriptions
    token_count = AudioHandler._get_token_count(
                  ^^^^^^^^^^^^^^^^^^^^^^^^^^^^^^
TypeError: AudioHandler._get_token_count() got an unexpected keyword argument 'provider_instance'
 {
    "error": {
        "message": "Traceback (most recent call last):\n  File \"/app/src/api/routes/v1/audio/transcriptions.py\", line 54, in audio_transcriptions\n    token_count = AudioHandler._get_token_count(\n                  ^^^^^^^^^^^^^^^^^^^^^^^^^^^^^^\nTypeError: AudioHandler._get_token_count() got an unexpected keyword argument 'provider_instance'\n", 
        "type": "invalid_request_error", 
        "code": 500
    }
} 500 {'error': {'message': 'Traceback (most recent call last):\n  File "/app/src/api/routes/v1/audio/transcriptions.py", line 54, in audio_transcriptions\n    token_count = AudioHandler._get_token_count(\n                  ^^^^^^^^^^^^^^^^^^^^^^^^^^^^^^\nTypeError: AudioHandler._get_token_count() got an unexpected keyword argument \'provider_instance\'\n', 'type': 'invalid_request_error', 'code': 500}} {'Date': 'Sun, 22 Dec 2024 05:08:59 GMT', 'Content-Type': 'application/json', 'Content-Length': '438', 'Connection': 'keep-alive', 'cf-cache-status': 'DYNAMIC', 'Report-To': '{"endpoints":[{"url":"https:\\/\\/a.nel.cloudflare.com\\/report\\/v4?s=z1EuNN12ircwySS1TJYiOJVs6QDTjj7OfNghqdTnvVHs5ASw3Bzu1WtOpbUjxBBdsQc1V18Rr3zjc2tFdMXTWTUweRkH0ew69j14sryTs3iPzQp362RzT2P5lZfpUjbR7tUAO4x1"}],"group":"cf-nel","max_age":604800}', 'NEL': '{"success_fraction":0,"report_to":"cf-nel","max_age":604800}', 'Server': 'cloudflare', 'CF-RAY': '8f5d98d6b9e43da5-SIN', 'alt-svc': 'h3=":443"; ma=86400', 'server-timing': 'cfL4;desc="?proto=TCP&rtt=15853&min_rtt=15788&rtt_var=6051&sent=145&recv=202&lost=0&retrans=0&sent_bytes=2851&recv_bytes=268142&delivery_rate=259717&cwnd=252&unsent_bytes=0&cid=47ee47b5d3e464f8&ts=1835&x=0"'}
2024-12-22 12:10:57,374 - ERROR - Error loading message history: Expecting value: line 1 column 1 (char 0)
2024-12-22 12:11:05,576 - ERROR - Error in talking_mode: Traceback (most recent call last):
  File "/app/src/api/routes/v1/audio/transcriptions.py", line 54, in audio_transcriptions
    token_count = AudioHandler._get_token_count(
                  ^^^^^^^^^^^^^^^^^^^^^^^^^^^^^^
TypeError: AudioHandler._get_token_count() got an unexpected keyword argument 'provider_instance'
 {
    "error": {
        "message": "Traceback (most recent call last):\n  File \"/app/src/api/routes/v1/audio/transcriptions.py\", line 54, in audio_transcriptions\n    token_count = AudioHandler._get_token_count(\n                  ^^^^^^^^^^^^^^^^^^^^^^^^^^^^^^\nTypeError: AudioHandler._get_token_count() got an unexpected keyword argument 'provider_instance'\n", 
        "type": "invalid_request_error", 
        "code": 500
    }
} 500 {'error': {'message': 'Traceback (most recent call last):\n  File "/app/src/api/routes/v1/audio/transcriptions.py", line 54, in audio_transcriptions\n    token_count = AudioHandler._get_token_count(\n                  ^^^^^^^^^^^^^^^^^^^^^^^^^^^^^^\nTypeError: AudioHandler._get_token_count() got an unexpected keyword argument \'provider_instance\'\n', 'type': 'invalid_request_error', 'code': 500}} {'Date': 'Sun, 22 Dec 2024 05:11:05 GMT', 'Content-Type': 'application/json', 'Content-Length': '438', 'Connection': 'keep-alive', 'cf-cache-status': 'DYNAMIC', 'Report-To': '{"endpoints":[{"url":"https:\\/\\/a.nel.cloudflare.com\\/report\\/v4?s=096N%2BRSpx%2B%2FSEjkw3Vptiup5YQtuIGeOM8hmDIeX%2BOL4JGCfTIk3wVUhWGmkpQ66dnuT%2F76yuS7cnuroDvx9plHodR%2FV5nsIguJDWUkGWteFPlsIHayGDXvSZK1Lr4hxmtrK0htX"}],"group":"cf-nel","max_age":604800}', 'NEL': '{"success_fraction":0,"report_to":"cf-nel","max_age":604800}', 'Server': 'cloudflare', 'CF-RAY': '8f5d9be5eb6afd33-SIN', 'alt-svc': 'h3=":443"; ma=86400', 'server-timing': 'cfL4;desc="?proto=TCP&rtt=15233&min_rtt=14960&rtt_var=6157&sent=136&recv=190&lost=0&retrans=0&sent_bytes=2851&recv_bytes=253784&delivery_rate=246997&cwnd=252&unsent_bytes=0&cid=4115b17b9394010c&ts=2049&x=0"'}
2024-12-22 12:11:52,468 - ERROR - Error loading message history: Expecting value: line 1 column 1 (char 0)
2024-12-22 12:17:48,413 - ERROR - Error loading message history: Expecting value: line 1 column 1 (char 0)
2024-12-24 07:36:35,433 - ERROR - Error loading message history: Expecting value: line 1 column 1 (char 0)
2024-12-24 07:55:06,217 - ERROR - Error getting chatbot response: Your IP is different than the locked one. Reset your IP lock at: http://discord.gg/zukijourney
2024-12-24 08:12:00,568 - ERROR - Error loading message history: Expecting value: line 1 column 1 (char 0)
2024-12-24 08:15:33,792 - ERROR - Error loading message history: Expecting value: line 1 column 1 (char 0)
2024-12-24 09:06:26,172 - ERROR - Error loading message history: Expecting value: line 1 column 1 (char 0)
2024-12-24 09:45:57,083 - ERROR - Error loading message history: Expecting value: line 1 column 1 (char 0)
2024-12-24 09:50:52,252 - ERROR - Error loading message history: Expecting value: line 1 column 1 (char 0)
2024-12-24 11:07:52,243 - ERROR - Error loading message history: Expecting value: line 1 column 1 (char 0)
2024-12-27 15:11:19,524 - ERROR - Error loading message history: Expecting value: line 1 column 1 (char 0)
2024-12-27 15:12:19,679 - ERROR - Error getting chatbot response: Your IP is different than the locked one. Reset your IP lock at: http://discord.gg/zukijourney
2024-12-27 15:19:28,683 - ERROR - Error loading message history: Expecting value: line 1 column 1 (char 0)
2024-12-27 15:19:40,974 - ERROR - Error getting chatbot response: Your IP is different than the locked one. Reset your IP lock at: http://discord.gg/zukijourney
2024-12-27 15:22:03,080 - ERROR - Error loading message history: Expecting value: line 1 column 1 (char 0)
2024-12-27 15:26:52,847 - ERROR - Error loading message history: Expecting value: line 1 column 1 (char 0)
2024-12-27 15:27:04,163 - ERROR - Error getting chatbot response: Your IP is different than the locked one. Reset your IP lock at: http://discord.gg/zukijourney
2024-12-27 15:28:16,301 - ERROR - Error getting chatbot response: Your IP is different than the locked one. Reset your IP lock at: http://discord.gg/zukijourney
2024-12-27 15:28:39,284 - ERROR - Error in talking_mode: 
2024-12-27 15:28:39,287 - ERROR - Exception in callback BaseProactorEventLoop._start_serving.<locals>.loop(<_OverlappedF...100', 51061))>) at C:\Users\Slavus\AppData\Local\Programs\Python\Python310\lib\asyncio\proactor_events.py:817
handle: <Handle BaseProactorEventLoop._start_serving.<locals>.loop(<_OverlappedF...100', 51061))>) at C:\Users\Slavus\AppData\Local\Programs\Python\Python310\lib\asyncio\proactor_events.py:817>
Traceback (most recent call last):
  File "C:\Users\Slavus\AppData\Local\Programs\Python\Python310\lib\asyncio\events.py", line 80, in _run
    self._context.run(self._callback, *self._args)
  File "C:\Users\Slavus\AppData\Local\Programs\Python\Python310\lib\asyncio\proactor_events.py", line 831, in loop
    self._make_socket_transport(
  File "C:\Users\Slavus\AppData\Local\Programs\Python\Python310\lib\asyncio\proactor_events.py", line 638, in _make_socket_transport
    return _ProactorSocketTransport(self, sock, protocol, waiter,
  File "C:\Users\Slavus\AppData\Local\Programs\Python\Python310\lib\asyncio\proactor_events.py", line 604, in __init__
    super().__init__(loop, sock, protocol, waiter, extra, server)
  File "C:\Users\Slavus\AppData\Local\Programs\Python\Python310\lib\asyncio\proactor_events.py", line 185, in __init__
    super().__init__(loop, sock, protocol, waiter, extra, server)
  File "C:\Users\Slavus\AppData\Local\Programs\Python\Python310\lib\asyncio\proactor_events.py", line 330, in __init__
    super().__init__(*args, **kw)
  File "C:\Users\Slavus\AppData\Local\Programs\Python\Python310\lib\asyncio\proactor_events.py", line 65, in __init__
    self._server._attach()
  File "C:\Users\Slavus\AppData\Local\Programs\Python\Python310\lib\asyncio\base_events.py", line 292, in _attach
    assert self._sockets is not None
AssertionError
2024-12-27 15:28:43,119 - ERROR - Error loading message history: Expecting value: line 1 column 1 (char 0)
2024-12-27 15:29:43,450 - ERROR - Error loading message history: Expecting value: line 1 column 1 (char 0)
2024-12-27 15:31:25,940 - ERROR - Error loading message history: Expecting value: line 1 column 1 (char 0)
2024-12-27 16:24:06,661 - ERROR - Error loading message history: Expecting value: line 1 column 1 (char 0)
2024-12-27 16:24:16,490 - ERROR - Error loading message history: Expecting value: line 1 column 1 (char 0)
2024-12-27 16:24:45,895 - ERROR - Error loading message history: Expecting value: line 1 column 1 (char 0)
2024-12-27 16:35:34,283 - ERROR - Error loading message history: Expecting value: line 1 column 1 (char 0)
2024-12-27 16:36:38,658 - ERROR - Error loading message history: Expecting value: line 1 column 1 (char 0)
2024-12-28 07:05:27,860 - ERROR - Error loading message history: Expecting value: line 1 column 1 (char 0)
2024-12-28 07:10:29,471 - ERROR - Error loading message history: Expecting value: line 1 column 1 (char 0)
2024-12-28 07:55:37,402 - ERROR - Error loading message history: Expecting value: line 1 column 1 (char 0)
2024-12-28 07:59:08,207 - ERROR - Error loading message history: Expecting value: line 1 column 1 (char 0)
2024-12-28 10:02:26,450 - ERROR - Error loading message history: Expecting value: line 1 column 1 (char 0)
2024-12-28 10:04:57,587 - ERROR - Error loading message history: Expecting value: line 1 column 1 (char 0)
2024-12-28 10:18:42,142 - ERROR - Error loading message history: Expecting value: line 1 column 1 (char 0)
2024-12-28 10:42:07,689 - ERROR - Error loading message history: Expecting value: line 1 column 1 (char 0)
2024-12-28 10:43:15,673 - ERROR - Error loading message history: Expecting value: line 1 column 1 (char 0)
2024-12-29 06:28:47,524 - ERROR - Error loading message history: Expecting value: line 1 column 1 (char 0)
2024-12-29 06:28:56,526 - ERROR - Error loading message history: Expecting value: line 1 column 1 (char 0)
2024-12-29 07:01:09,610 - ERROR - Error loading message history: Expecting value: line 1 column 1 (char 0)
2024-12-29 09:20:52,110 - ERROR - Error loading message history: Expecting value: line 1 column 1 (char 0)
2024-12-29 10:57:58,362 - ERROR - Error loading message history: Expecting value: line 1 column 1 (char 0)
2024-12-29 11:11:44,519 - ERROR - Error loading message history: Expecting value: line 1 column 1 (char 0)
2024-12-29 11:24:01,357 - ERROR - Error getting chatbot response: Your IP is different than the locked one. Reset your IP lock at: http://discord.gg/zukijourney
2024-12-30 08:00:40,264 - ERROR - Error loading message history: Expecting value: line 1 column 1 (char 0)
2024-12-30 08:00:54,982 - ERROR - Error loading message history: Expecting value: line 1 column 1 (char 0)
2024-12-30 08:05:27,559 - ERROR - Error loading message history: Expecting value: line 1 column 1 (char 0)
2024-12-30 08:43:13,337 - ERROR - Error loading message history: Expecting value: line 1 column 1 (char 0)
2024-12-30 09:00:37,076 - ERROR - Error getting chatbot response: Your IP is different than the locked one. Reset your IP lock at: http://discord.gg/zukijourney
2025-01-01 07:49:06,861 - ERROR - Error loading message history: Expecting value: line 1 column 1 (char 0)
2025-01-01 07:53:33,067 - ERROR - Error getting chatbot response: Your IP is different than the locked one. Reset your IP lock at: http://discord.gg/zukijourney
2025-01-01 07:54:31,252 - ERROR - Error loading message history: Expecting value: line 1 column 1 (char 0)
2025-01-01 08:17:36,805 - ERROR - Error loading message history: Expecting value: line 1 column 1 (char 0)
2025-01-01 08:26:39,092 - ERROR - Error loading message history: Expecting value: line 1 column 1 (char 0)
2025-01-01 08:26:57,608 - ERROR - Error in start_talking_mode: 
2025-01-01 08:28:36,707 - ERROR - Error loading message history: Expecting value: line 1 column 1 (char 0)
2025-01-01 08:29:23,239 - ERROR - Error in start_talking_mode: This audio source is already inside a context manager
2025-01-01 08:29:32,689 - ERROR - Error in start_talking_mode: This audio source is already inside a context manager
2025-01-01 08:29:33,353 - ERROR - Error in start_talking_mode: This audio source is already inside a context manager
2025-01-01 08:29:33,730 - ERROR - Error in start_talking_mode: This audio source is already inside a context manager
2025-01-01 08:29:34,070 - ERROR - Error in start_talking_mode: This audio source is already inside a context manager
2025-01-01 08:29:34,395 - ERROR - Error in start_talking_mode: This audio source is already inside a context manager
2025-01-01 08:29:34,740 - ERROR - Error in start_talking_mode: This audio source is already inside a context manager
2025-01-01 08:31:41,721 - ERROR - Error loading message history: Expecting value: line 1 column 1 (char 0)
2025-01-01 08:32:07,419 - ERROR - Error loading message history: Expecting value: line 1 column 1 (char 0)
2025-01-01 08:32:22,924 - ERROR - Error in start_talking_mode: 
2025-01-01 08:35:48,625 - ERROR - Error loading message history: Expecting value: line 1 column 1 (char 0)
2025-01-01 08:37:34,579 - ERROR - Error loading message history: Expecting value: line 1 column 1 (char 0)
2025-01-01 08:38:28,042 - ERROR - Error in get_user_input: 
2025-01-01 08:39:16,152 - ERROR - Error in get_user_input: 
2025-01-01 08:44:52,117 - ERROR - Error loading message history: Expecting value: line 1 column 1 (char 0)
2025-01-01 08:45:53,834 - ERROR - Error loading message history: Expecting value: line 1 column 1 (char 0)
2025-01-01 08:54:19,165 - ERROR - Error loading message history: Expecting value: line 1 column 1 (char 0)
2025-01-01 08:57:13,649 - ERROR - Error loading message history: Expecting value: line 1 column 1 (char 0)
2025-01-01 08:58:18,675 - ERROR - Error loading message history: Expecting value: line 1 column 1 (char 0)
2025-01-01 08:58:23,303 - ERROR - Error loading message history: Expecting value: line 1 column 1 (char 0)
2025-01-01 08:59:24,564 - ERROR - Error loading message history: Expecting value: line 1 column 1 (char 0)
2025-01-01 09:01:12,535 - ERROR - Error loading message history: Expecting value: line 1 column 1 (char 0)
2025-01-01 09:09:24,344 - ERROR - Error loading message history: Expecting value: line 1 column 1 (char 0)
2025-01-01 09:15:29,385 - ERROR - Error loading message history: Expecting value: line 1 column 1 (char 0)
2025-01-01 09:19:43,054 - ERROR - Error loading message history: Expecting value: line 1 column 1 (char 0)
2025-01-01 09:21:04,828 - ERROR - Error loading message history: Expecting value: line 1 column 1 (char 0)
2025-01-01 09:22:04,959 - ERROR - Error loading message history: Expecting value: line 1 column 1 (char 0)
